Workbook

Sheet Quadro Geral
D1: Análise da descrição | H1: Questões com imagens
B2: Prova | C2: Número de Questões | D2: Critério A | E2: Critério AA | F2: Critério AAA | H2: Critério A | I2: Critério AA | J2: Critério AAA
B3: 2008 | C3: 20 | F3: =COUNTIF('2008'!B2:B21,"*3A*") -> 20 | H3: =COUNTIFS('2008'!B2:B21,"*1A*",'2008'!C2:C21,"Sim") -> 0 | I3: =COUNTIFS('2008'!B2:B21,"*2A*",'2008'!C2:C21,"Sim") -> 0 | J3: =COUNTIFS('2008'!B2:B21,"*3A*",'2008'!C2:C21,"Sim") -> 0
B4: 2009 | C4: 20 | F4: =COUNTIF('2009'!$B:$B,"*3A*") -> 20 | H4: =COUNTIFS('2009'!B2:B21,"*1A*",'2009'!C2:C21,"Sim") -> 0 | I4: =COUNTIFS('2009'!B2:B21,"*2A*",'2009'!C2:C21,"Sim") -> 0 | J4: =COUNTIFS('2009'!B2:B21,"*3A*",'2009'!C2:C21,"Sim") -> 0
B5: 2010 | C5: 20 | F5: =COUNTIF('2010'!$B:$B,"*3A*") -> 20 | H5: =COUNTIFS('2010'!B2:B21,"*1A*",'2010'!C2:C21,"Sim") -> 0 | I5: =COUNTIFS('2010'!B2:B21,"*2A*",'2010'!C2:C21,"Sim") -> 0 | J5: =COUNTIFS('2010'!B2:B21,"*3A*",'2010'!C2:C21,"Sim") -> 0
B6: 2011 | C6: 20 | F6: =COUNTIF('2011'!$B:$B,"*3A*") -> 20 | H6: =COUNTIFS('2011'!B2:B21,"*1A*",'2011'!C2:C21,"Sim") -> 0 | I6: =COUNTIFS('2011'!B2:B21,"*2A*",'2011'!C2:C21,"Sim") -> 0 | J6: =COUNTIFS('2011'!B2:B21,"*3A*",'2011'!C2:C21,"Sim") -> 5
B7: 2012 | C7: 20 | D7: =COUNTIF('2012'!$B:$B,"*1A*") -> 5 | F7: =COUNTIF('2012'!$B:$B,"*3A*") -> 15 | H7: =COUNTIFS('2012'!B:B,"*1A*",'2012'!C:C,"Sim") -> 5 | I7: =COUNTIFS('2012'!B:B,"*2A*",'2012'!C:C,"Sim") -> 0 | J7: =COUNTIFS('2012'!B:B,"*3A*",'2012'!C:C,"Sim") -> 0
B8: 2013 | C8: 20 | F8: =COUNTIF('2013'!$B:$B,"*3A*") -> 20 | H8: =COUNTIFS('2013'!B:B,"*1A*",'2013'!C:C,"Sim") -> 0 | I8: =COUNTIFS('2013'!B:B,"*2A*",'2013'!C:C,"Sim") -> 0 | J8: =COUNTIFS('2013'!B:B,"*3A*",'2013'!C:C,"Sim") -> 0
B9: 2014 | C9: 25 | D9: =COUNTIF('2014'!$B:$B,"*1A*") -> 3 | F9: =COUNTIF('2014'!$B:$B,"*3A*") -> 22 | H9: =COUNTIFS('2014'!B:B,"*1A*",'2014'!C:C,"Sim") -> 3 | I9: =COUNTIFS('2014'!B:B,"*2A*",'2014'!C:C,"Sim") -> 0 | J9: =COUNTIFS('2014'!B:B,"*3A*",'2014'!C:C,"Sim") -> 0
B10: 2015 | C10: 25 | D10: =COUNTIF('2015'!$B:$B,"*1A*") -> 4 | F10: =COUNTIF('2015'!$B:$B,"*3A*") -> 21 | H10: =COUNTIFS('2015'!B:B,"*1A*",'2015'!C:C,"Sim") -> 4 | I10: =COUNTIFS('2015'!B:B,"*2A*",'2015'!C:C,"Sim") -> 0 | J10: =COUNTIFS('2015'!B:B,"*3A*",'2015'!C:C,"Sim") -> 1
B11: 2016 | C11: 25 | D11: =COUNTIF('2016'!$B:$B,"*1A*") -> 6 | F11: =COUNTIF('2016'!$B:$B,"*3A*") -> 19 | H11: =COUNTIFS('2016'!B:B,"*1A*",'2016'!C:C,"Sim") -> 6 | I11: =COUNTIFS('2016'!B:B,"*2A*",'2016'!C:C,"Sim") -> 0 | J11: =COUNTIFS('2016'!B:B,"*3A*",'2016'!C:C,"Sim") -> 0
B12: 2017 | C12: 15 | F12: =COUNTIF('2017'!$B:$B,"*3A*") -> 15 | H12: =COUNTIFS('2017'!B:B,"*1A*",'2017'!C:C,"Sim") -> 0 | I12: =COUNTIFS('2017'!B:B,"*2A*",'2017'!C:C,"Sim") -> 0 | J12: =COUNTIFS('2017'!B:B,"*3A*",'2017'!C:C,"Sim") -> 0
B13: 2018 (nível 1) | C13: 15 | D13: =COUNTIF('2018 N1'!$B:$B,"*1A*") -> 6 | F13: =COUNTIF('2018 N1'!$B:$B,"*3A*") -> 9 | H13: =COUNTIFS('2018 N1'!B:B,"*1A*",'2018 N1'!C:C,"Sim") -> 6 | I13: =COUNTIFS('2018 N1'!B:B,"*2A*",'2018 N1'!C:C,"Sim") -> 0 | J13: =COUNTIFS('2018 N1'!B:B,"*3A*",'2018 N1'!C:C,"Sim") -> 0
B14: 2018 (nível junior) | C14: 15 | D14: =COUNTIF('2018 N J'!$B:$B,"*1A*") -> 6 | F14: =COUNTIF('2018 N J'!$B:$B,"*3A*") -> 9 | H14: =COUNTIFS('2018 N J'!B:B,"*1A*",'2018 N J'!C:C,"Sim") -> 6 | I14: =COUNTIFS('2018 N J'!B:B,"*2A*",'2018 N J'!C:C,"Sim") -> 0 | J14: =COUNTIFS('2018 N J'!B:B,"*3A*",'2018 N J'!C:C,"Sim") -> 0
B15: 2019 (nível 1) | C15: 15 | D15: =COUNTIF('2019 N1'!$B:$B,"*1A*") -> 4 | F15: =COUNTIF('2019 N1'!$B:$B,"*3A*") -> 11 | H15: =COUNTIFS('2019 N1'!B:B,"*1A*",'2019 N1'!C:C,"Sim") -> 4 | I15: =COUNTIFS('2019 N1'!B:B,"*2A*",'2019 N1'!C:C,"Sim") -> 0 | J15: =COUNTIFS('2019 N1'!B:B,"*3A*",'2019 N1'!C:C,"Sim") -> 0
B16: 2019 (nível junior) | C16: 15 | D16: =COUNTIF('2019 N J'!$B:$B,"*1A*") -> 5 | F16: =COUNTIF('2019 N J'!$B:$B,"*3A*") -> 10 | H16: =COUNTIFS('2019 N J'!B:B,"*1A*",'2019 N J'!C:C,"Sim") -> 5 | I16: =COUNTIFS('2019 N J'!B:B,"*2A*",'2019 N J'!C:C,"Sim") -> 0 | J16: =COUNTIFS('2019 N J'!B:B,"*3A*",'2019 N J'!C:C,"Sim") -> 3
B17: 2020 (nível 1, tipo A) | C17: 15 | D17: =COUNTIF('2020 N1 A'!$B:$B,"*1A*") -> 3 | F17: =COUNTIF('2020 N1 A'!$B:$B,"*3A*") -> 12 | H17: =COUNTIFS('2020 N1 A'!B:B,"*1A*",'2020 N1 A'!C:C,"Sim") -> 3 | I17: =COUNTIFS('2020 N1 A'!B:B,"*2A*",'2020 N1 A'!C:C,"Sim") -> 0 | J17: =COUNTIFS('2020 N1 A'!B:B,"*3A*",'2020 N1 A'!C:C,"Sim") -> 0
B18: 2020 (nível 1, tipo B) | C18: 15 | D18: =COUNTIF('2020 N1 B'!$B:$B,"*1A*") -> 6 | F18: =COUNTIF('2020 N1 B'!$B:$B,"*3A*") -> 9 | H18: =COUNTIFS('2020 N1 B'!B:B,"*1A*",'2020 N1 B'!C:C,"Sim") -> 6 | I18: =COUNTIFS('2020 N1 B'!B:B,"*2A*",'2020 N1 B'!C:C,"Sim") -> 0 | J18: =COUNTIFS('2020 N1 B'!B:B,"*3A*",'2020 N1 B'!C:C,"Sim") -> 0
B19: 2020 (nível junior, tipo A) | C19: 15 | D19: =COUNTIF('2020 J A'!$B:$B,"*1A*") -> 5 | F19: =COUNTIF('2020 J A'!$B:$B,"*3A*") -> 10 | H19: =COUNTIFS('2020 J A'!B:B,"*1A*",'2020 J A'!C:C,"Sim") -> 5 | I19: =COUNTIFS('2020 J A'!B:B,"*2A*",'2020 J A'!C:C,"Sim") -> 0 | J19: =COUNTIFS('2020 J A'!B:B,"*3A*",'2020 J A'!C:C,"Sim") -> 0
B20: 2020 (nível junior, tipo B) | C20: 15 | D20: =COUNTIF('2020 J B'!$B:$B,"*1A*") -> 6 | F20: =COUNTIF('2020 J B'!$B:$B,"*3A*") -> 9 | H20: =COUNTIFS('2020 J B'!B:B,"*1A*",'2020 J B'!C:C,"Sim") -> 6 | I20: =COUNTIFS('2020 J B'!B:B,"*2A*",'2020 J B'!C:C,"Sim") -> 0 | J20: =COUNTIFS('2020 J B'!B:B,"*3A*",'2020 J B'!C:C,"Sim") -> 0
B21: 2021 (nível 1) | C21: 15 | F21: =COUNTIF('2021 N1'!$B:$B,"*3A*") -> 15 | H21: =COUNTIFS('2021 N1'!B:B,"*1A*",'2021 N1'!C:C,"Sim") -> 0 | I21: =COUNTIFS('2021 N1'!B:B,"*2A*",'2021 N1'!C:C,"Sim") -> 0 | J21: =COUNTIFS('2021 N1'!B:B,"*3A*",'2021 N1'!C:C,"Sim") -> 0
B22: 2021 (nível junior) | C22: 15 | D22: =COUNTIF('2021 NJ'!$B:$B,"*1A*") -> 3 | F22: =COUNTIF('2021 NJ'!$B:$B,"*3A*") -> 12 | H22: =COUNTIFS('2021 NJ'!B:B,"*1A*",'2021 NJ'!C:C,"Sim") -> 3 | I22: =COUNTIFS('2021 NJ'!B:B,"*2A*",'2021 NJ'!C:C,"Sim") -> 0 | J22: =COUNTIFS('2021 NJ'!B:B,"*3A*",'2021 NJ'!C:C,"Sim") -> 0
B23: 2022 (nível 1) | C23: 15 | D23: =COUNTIF('2022 N 1'!$B:$B,"*1A*") -> 3 | F23: =COUNTIF('2022 N 1'!$B:$B,"*3A*") -> 12 | H23: =COUNTIFS('2022 N 1'!B:B,"*1A*",'2022 N 1'!C:C,"Sim") -> 3 | I23: =COUNTIFS('2022 N 1'!B:B,"*2A*",'2022 N 1'!C:C,"Sim") -> 0 | J23: =COUNTIFS('2022 N 1'!B:B,"*3A*",'2022 N 1'!C:C,"Sim") -> 2
B24: 2022 (nível junior) | C24: 15 | D24: =COUNTIF('2022 N J'!$B:$B,"*1A*") -> 2 | F24: =COUNTIF('2022 N J'!$B:$B,"*3A*") -> 13 | H24: =COUNTIFS('2022 N J'!B:B,"*1A*",'2022 N J'!C:C,"Sim") -> 2 | I24: =COUNTIFS('2022 N J'!B:B,"*2A*",'2022 N J'!C:C,"Sim") -> 0 | J24: =COUNTIFS('2022 N J'!B:B,"*3A*",'2022 N J'!C:C,"Sim") -> 7
B25: 2023 (nível 1) | C25: 15 | D25: =COUNTIF('2023 N1'!$B:$B,"*1A*") -> 1 | F25: =COUNTIF('2023 N1'!$B:$B,"*3A*") -> 14 | H25: =COUNTIFS('2023 N1'!B:B,"*1A*",'2023 N1'!C:C,"Sim") -> 1 | I25: =COUNTIFS('2023 N1'!B:B,"*2A*",'2023 N1'!C:C,"Sim") -> 0 | J25: =COUNTIFS('2023 N1'!B:B,"*3A*",'2023 N1'!C:C,"Sim") -> 0
B26: 2023 (nível junior) | C26: 15 | D26: =COUNTIF('2023 NJ'!$B:$B,"*1A*") -> 1 | F26: =COUNTIF('2023 NJ'!$B:$B,"*3A*") -> 14 | H26: =COUNTIFS('2023 NJ'!B:B,"*1A*",'2023 NJ'!C:C,"Sim") -> 1 | I26: =COUNTIFS('2023 NJ'!B:B,"*2A*",'2023 NJ'!C:C,"Sim") -> 0 | J26: =COUNTIFS('2023 NJ'!B:B,"*3A*",'2023 NJ'!C:C,"Sim") -> 0
B27: 2024 (nível 1) | C27: 15 | D27: =COUNTIF('2024 N1'!$B:$B,"*1A*") -> 5 | E27: =COUNTIF('2024 N1'!$B:$B,"*2A*") -> 0 | F27: =COUNTIF('2024 N1'!$B:$B,"*3A*") -> 10 | H27: =COUNTIFS('2024 N1'!B:B,"*1A*",'2024 N1'!C:C,"Sim") -> 5 | I27: =COUNTIFS('2024 N1'!B:B,"*2A*",'2024 N1'!C:C,"Sim") -> 0 | J27: =COUNTIFS('2024 N1'!B:B,"*3A*",'2024 N1'!C:C,"Sim") -> 0
B28: 2024 (nível junior) | C28: 15 | D28: =COUNTIF('2024 NJ'!$B:$B,"*1A*") -> 6 | F28: =COUNTIF('2024 NJ'!$B:$B,"*3A*") -> 9 | H28: =COUNTIFS('2024 NJ'!B:B,"*1A*",'2024 NJ'!C:C,"Sim") -> 6 | I28: =COUNTIFS('2024 NJ'!B:B,"*2A*",'2024 NJ'!C:C,"Sim") -> 0 | J28: =COUNTIFS('2024 NJ'!B:B,"*3A*",'2024 NJ'!C:C,"Sim") -> 4
B29: Total | C29: =SUM(C3:C28) -> 450 | D29: =SUM(D3:D28) -> 80 | E29: =SUM(E3:E28) -> 0 | F29: =SUM(F3:F28) -> 370 | H29: =SUM(H3:H28) -> 80 | I29: =SUM(I3:I28) -> 0 | J29: =SUM(J3:J28) -> 22
B30: Porcentagem | C30: =(100*C29)/C29 -> 100 | D30: =(100*D29)/C29 -> 17.777778 | E30: =(100*E29)/C29 -> 0 | F30: =(100*F29)/C29 -> 82.222222 | H30: =(H29*100)/D29 -> 100 | I30: 0 | J30: =(J29*100)/F29 -> 5.9459459

Sheet Elementos Visuais
D1: Questões com Elementos Visuais
B3: Prova | C3: Número de Questões | D3: Critério A | E3: Critério AA | F3: Critério AAA
B4: 2008 | C4: 20
B5: 2009 | C5: 20
B6: 2010 | C6: 20
B7: 2011 | C7: 20 | F7: 5
B8: 2012 | C8: 20 | D8: 5
B9: 2013 | C9: 20
B10: 2014 | C10: 25 | D10: 3
B11: 2015 | C11: 25 | D11: 4 | F11: 1
B12: 2016 | C12: 25 | D12: 6
B13: 2017 | C13: 15
B14: 2018 (nível 1) | C14: 15 | D14: 6
B15: 2018 (nível junior) | C15: 15 | D15: 6
B16: 2019 (nível 1) | C16: 15 | D16: 4
B17: 2019 (nível junior) | C17: 15 | D17: 5 | F17: 3
B18: 2020 (nível 1, tipo A) | C18: 15 | D18: 3
B19: 2020 (nível 1, tipo B) | C19: 15 | D19: 6
B20: 2020 (nível junior, tipo A) | C20: 15 | D20: 5
B21: 2020 (nível junior, tipo B) | C21: 15 | D21: 6
B22: 2021 (nível 1) | C22: 15
B23: 2021 (nível junior) | C23: 15 | D23: 3
B24: 2022 (nível 1) | C24: 15 | D24: 3 | F24: 2
B25: 2022 (nível junior) | C25: 15 | D25: 2 | F25: 7
B26: 2023 (nível 1) | C26: 15 | D26: 1
B27: 2023 (nível junior) | C27: 15 | D27: 1
B28: 2024 (nível 1) | C28: 15 | D28: 5
B29: 2024 (nível junior) | C29: 15 | D29: 6 | F29: 4
D30: =SUM(D4:D29) -> 80 | F30: =SUM(F4:F29) -> 22

Sheet 2008
A1: Questão | B1: Critério de Acessibilidade Atribuído | C1: Elementos Visuais
A2: 1 | B2: Critério 3A (Descrição suficiente e tempo suficiente) —A descrição apresenta de maneira devida todos os elementos indispensáveis ao entendimento do item em tempo adequado para a resolução. | C2: Não
A3: 2 | B3: Critério 3A (Descrição suficiente e tempo suficiente) —A descrição apresenta de maneira devida todos os elementos indispensáveis ao entendimento do item em tempo adequado para a resolução. | C3: Não
A4: 3 | B4: Critério 3A (Descrição suficiente e tempo suficiente) —A descrição apresenta de maneira devida todos os elementos indispensáveis ao entendimento do item em tempo adequado para a resolução. | C4: Não
A5: 4 | B5: Critério 3A (Descrição suficiente e tempo suficiente) —A descrição apresenta de maneira devida todos os elementos indispensáveis ao entendimento do item em tempo adequado para a resolução. | C5: Não
A6: 5 | B6: Critério 3A (Descrição suficiente e tempo suficiente) —A descrição apresenta de maneira devida todos os elementos indispensáveis ao entendimento do item em tempo adequado para a resolução. | C6: Não
A7: 6 | B7: Critério 3A (Descrição suficiente e tempo suficiente) —A descrição apresenta de maneira devida todos os elementos indispensáveis ao entendimento do item em tempo adequado para a resolução. | C7: Não
A8: 7 | B8: Critério 3A (Descrição suficiente e tempo suficiente) —A descrição apresenta de maneira devida todos os elementos indispensáveis ao entendimento do item em tempo adequado para a resolução. | C8: Não
A9: 8 | B9: Critério 3A (Descrição suficiente e tempo suficiente) —A descrição apresenta de maneira devida todos os elementos indispensáveis ao entendimento do item em tempo adequado para a resolução. | C9: Não
A10: 9 | B10: Critério 3A (Descrição suficiente e tempo suficiente) —A descrição apresenta de maneira devida todos os elementos indispensáveis ao entendimento do item em tempo adequado para a resolução. | C10: Não
A11: 10 | B11: Critério 3A (Descrição suficiente e tempo suficiente) —A descrição apresenta de maneira devida todos os elementos indispensáveis ao entendimento do item em tempo adequado para a resolução. | C11: Não
A12: 11 | B12: Critério 3A (Descrição suficiente e tempo suficiente) —A descrição apresenta de maneira devida todos os elementos indispensáveis ao entendimento do item em tempo adequado para a resolução. | C12: Não
A13: 12 | B13: Critério 3A (Descrição suficiente e tempo suficiente) —A descrição apresenta de maneira devida todos os elementos indispensáveis ao entendimento do item em tempo adequado para a resolução. | C13: Não
... A21: 20 | B21: Critério 3A (Descrição suficiente e tempo suficiente) —A descrição apresenta de maneira devida todos os elementos indispensáveis ao entendimento do item em tempo adequado para a resolução. | C21: Não

Sheet 2009
A1: Questão | B1: Critério de Acessibilidade Atribuído | C1: Elementos Visuais
A2: 1 | B2: Critério 3A (Descrição suficiente e tempo suficiente) —A descrição apresenta de maneira devida todos os elementos indispensáveis ao entendimento do item em tempo adequado para a resolução. | C2: Não
A3: 2 | B3: Critério 3A (Descrição suficiente e tempo suficiente) —A descrição apresenta de maneira devida todos os elementos indispensáveis ao entendimento do item em tempo adequado para a resolução. | C3: Não
A4: 3 | B4: Critério 3A (Descrição suficiente e tempo suficiente) —A descrição apresenta de maneira devida todos os elementos indispensáveis ao entendimento do item em tempo adequado para a resolução. | C4: Não
A5: 4 | B5: Critério 3A (Descrição suficiente e tempo suficiente) —A descrição apresenta de maneira devida todos os elementos indispensáveis ao entendimento do item em tempo adequado para a resolução. | C5: Não
A6: 5 | B6: Critério 3A (Descrição suficiente e tempo suficiente) —A descrição apresenta de maneira devida todos os elementos indispensáveis ao entendimento do item em tempo adequado para a resolução. | C6: Não
A7: 6 | B7: Critério 3A (Descrição suficiente e tempo suficiente) —A descrição apresenta de maneira devida todos os elementos indispensáveis ao entendimento do item em tempo adequado para a resolução. | C7: Não
A8: 7 | B8: Critério 3A (Descrição suficiente e tempo suficiente) —A descrição apresenta de maneira devida todos os elementos indispensáveis ao entendimento do item em tempo adequado para a resolução. | C8: Não
A9: 8 | B9: Critério 3A (Descrição suficiente e tempo suficiente) —A descrição apresenta de maneira devida todos os elementos indispensáveis ao entendimento do item em tempo adequado para a resolução. | C9: Não
A10: 9 | B10: Critério 3A (Descrição suficiente e tempo suficiente) —A descrição apresenta de maneira devida todos os elementos indispensáveis ao entendimento do item em tempo adequado para a resolução. | C10: Não
A11: 10 | B11: Critério 3A (Descrição suficiente e tempo suficiente) —A descrição apresenta de maneira devida todos os elementos indispensáveis ao entendimento do item em tempo adequado para a resolução. | C11: Não
A12: 11 | B12: Critério 3A (Descrição suficiente e tempo suficiente) —A descrição apresenta de maneira devida todos os elementos indispensáveis ao entendimento do item em tempo adequado para a resolução. | C12: Não
A13: 12 | B13: Critério 3A (Descrição suficiente e tempo suficiente) —A descrição apresenta de maneira devida todos os elementos indispensáveis ao entendimento do item em tempo adequado para a resolução. | C13: Não
... A21: 20 | B21: Critério 3A (Descrição suficiente e tempo suficiente) —A descrição apresenta de maneira devida todos os elementos indispensáveis ao entendimento do item em tempo adequado para a resolução. | C21: Não

Sheet 2010
A1: Questão | B1: Critério de Acessibilidade Atribuído | C1: Elementos Visuais
A2: 1 | B2: Critério 3A (Descrição suficiente e tempo suficiente) —A descrição apresenta de maneira devida todos os elementos indispensáveis ao entendimento do item em tempo adequado para a resolução. | C2: Não
A3: 2 | B3: Critério 3A (Descrição suficiente e tempo suficiente) —A descrição apresenta de maneira devida todos os elementos indispensáveis ao entendimento do item em tempo adequado para a resolução. | C3: Não
A4: 3 | B4: Critério 3A (Descrição suficiente e tempo suficiente) —A descrição apresenta de maneira devida todos os elementos indispensáveis ao entendimento do item em tempo adequado para a resolução. | C4: Não
A5: 4 | B5: Critério 3A (Descrição suficiente e tempo suficiente) —A descrição apresenta de maneira devida todos os elementos indispensáveis ao entendimento do item em tempo adequado para a resolução. | C5: Não
A6: 5 | B6: Critério 3A (Descrição suficiente e tempo suficiente) —A descrição apresenta de maneira devida todos os elementos indispensáveis ao entendimento do item em tempo adequado para a resolução. | C6: Não
A7: 6 | B7: Critério 3A (Descrição suficiente e tempo suficiente) —A descrição apresenta de maneira devida todos os elementos indispensáveis ao entendimento do item em tempo adequado para a resolução. | C7: Não
A8: 7 | B8: Critério 3A (Descrição suficiente e tempo suficiente) —A descrição apresenta de maneira devida todos os elementos indispensáveis ao entendimento do item em tempo adequado para a resolução. | C8: Não
A9: 8 | B9: Critério 3A (Descrição suficiente e tempo suficiente) —A descrição apresenta de maneira devida todos os elementos indispensáveis ao entendimento do item em tempo adequado para a resolução. | C9: Não
A10: 9 | B10: Critério 3A (Descrição suficiente e tempo suficiente) —A descrição apresenta de maneira devida todos os elementos indispensáveis ao entendimento do item em tempo adequado para a resolução. | C10: Não
A11: 10 | B11: Critério 3A (Descrição suficiente e tempo suficiente) —A descrição apresenta de maneira devida todos os elementos indispensáveis ao entendimento do item em tempo adequado para a resolução. | C11: Não
A12: 11 | B12: Critério 3A (Descrição suficiente e tempo suficiente) —A descrição apresenta de maneira devida todos os elementos indispensáveis ao entendimento do item em tempo adequado para a resolução. | C12: Não
A13: 12 | B13: Critério 3A (Descrição suficiente e tempo suficiente) —A descrição apresenta de maneira devida todos os elementos indispensáveis ao entendimento do item em tempo adequado para a resolução. | C13: Não
... A21: 20 | B21: Critério 3A (Descrição suficiente e tempo suficiente) —A descrição apresenta de maneira devida todos os elementos indispensáveis ao entendimento do item em tempo adequado para a resolução. | C21: Não

Sheet 2011
A1: Questão | B1: Critério de Acessibilidade Atribuído | C1: Elementos Visuais
A2: 1 | B2: Critério 3A (Descrição suficiente e tempo suficiente) —A descrição apresenta de maneira devida todos os elementos indispensáveis ao entendimento do item em tempo adequado para a resolução. | C2: Não
A3: 2 | B3: Critério 3A (Descrição suficiente e tempo suficiente) —A descrição apresenta de maneira devida todos os elementos indispensáveis ao entendimento do item em tempo adequado para a resolução. | C3: Não
A4: 3 | B4: Critério 3A (Descrição suficiente e tempo suficiente) —A descrição apresenta de maneira devida todos os elementos indispensáveis ao entendimento do item em tempo adequado para a resolução. | C4: Não
A5: 4 | B5: Critério 3A (Descrição suficiente e tempo suficiente) —A descrição apresenta de maneira devida todos os elementos indispensáveis ao entendimento do item em tempo adequado para a resolução. | C5: Não
A6: 5 | B6: Critério 3A (Descrição suficiente e tempo suficiente) —A descrição apresenta de maneira devida todos os elementos indispensáveis ao entendimento do item em tempo adequado para a resolução. | C6: Não
A7: 6 | B7: Critério 3A (Descrição suficiente e tempo suficiente) —A descrição apresenta de maneira devida todos os elementos indispensáveis ao entendimento do item em tempo adequado para a resolução. | C7: Não
A8: 7 | B8: Critério 3A (Descrição suficiente e tempo suficiente) —A descrição apresenta de maneira devida todos os elementos indispensáveis ao entendimento do item em tempo adequado para a resolução. | C8: Não
A9: 8 | B9: Critério 3A (Descrição suficiente e tempo suficiente) —A descrição apresenta de maneira devida todos os elementos indispensáveis ao entendimento do item em tempo adequado para a resolução. | C9: Não
A10: 9 | B10: Critério 3A (Descrição suficiente e tempo suficiente) —A descrição apresenta de maneira devida todos os elementos indispensáveis ao entendimento do item em tempo adequado para a resolução. | C10: Não
A11: 10 | B11: Critério 3A (Descrição suficiente e tempo suficiente) —A descrição apresenta de maneira devida todos os elementos indispensáveis ao entendimento do item em tempo adequado para a resolução. | C11: Não
A12: 11 | B12: Critério 3A (Descrição suficiente e tempo suficiente) —A descrição apresenta de maneira devida todos os elementos indispensáveis ao entendimento do item em tempo adequado para a resolução. | C12: Não
A13: 12 | B13: Critério 3A (Descrição suficiente e tempo suficiente) —A descrição apresenta de maneira devida todos os elementos indispensáveis ao entendimento do item em tempo adequado para a resolução. | C13: Não
... A21: 20 | B21: Critério 3A (Descrição suficiente e tempo suficiente) —A descrição apresenta de maneira devida todos os elementos indispensáveis ao entendimento do item em tempo adequado para a resolução. | C21: Sim

Sheet 2012
A1: Questão | B1: Critério de Acessibilidade Atribuído | C1: Elementos Visuais
A2: 1 | B2: Critério 3A (Descrição suficiente e tempo suficiente) —A descrição apresenta de maneira devida todos os elementos indispensáveis ao entendimento do item em tempo adequado para a resolução. | C2: Não
A3: 2 | B3: Critério 3A (Descrição suficiente e tempo suficiente) —A descrição apresenta de maneira devida todos os elementos indispensáveis ao entendimento do item em tempo adequado para a resolução. | C3: Não
A4: 3 | B4: Critério 1A (descrição insuficiente) – Um ou mais elementos indispensáveis ao entendimento do item não foram descritos e/ou podem não fazer parte do conhecimento imagético por parte da pessoa com deficiência visual. O participante possivelmente não será capaz de realizar o item por informações insuficientes na descrição. | C4: Sim
A5: 4 | B5: Critério 3A (Descrição suficiente e tempo suficiente) —A descrição apresenta de maneira devida todos os elementos indispensáveis ao entendimento do item em tempo adequado para a resolução. | C5: Não
A6: 5 | B6: Critério 1A (descrição insuficiente) – Um ou mais elementos indispensáveis ao entendimento do item não foram descritos e/ou podem não fazer parte do conhecimento imagético por parte da pessoa com deficiência visual. O participante possivelmente não será capaz de realizar o item por informações insuficientes na descrição. | C6: Sim
A7: 6 | B7: Critério 1A (descrição insuficiente) – Um ou mais elementos indispensáveis ao entendimento do item não foram descritos e/ou podem não fazer parte do conhecimento imagético por parte da pessoa com deficiência visual. O participante possivelmente não será capaz de realizar o item por informações insuficientes na descrição. | C7: Sim
A8: 7 | B8: Critério 3A (Descrição suficiente e tempo suficiente) —A descrição apresenta de maneira devida todos os elementos indispensáveis ao entendimento do item em tempo adequado para a resolução. | C8: Não
A9: 8 | B9: Critério 3A (Descrição suficiente e tempo suficiente) —A descrição apresenta de maneira devida todos os elementos indispensáveis ao entendimento do item em tempo adequado para a resolução. | C9: Não
A10: 9 | B10: Critério 1A (descrição insuficiente) – Um ou mais elementos indispensáveis ao entendimento do item não foram descritos e/ou podem não fazer parte do conhecimento imagético por parte da pessoa com deficiência visual. O participante possivelmente não será capaz de realizar o item por informações insuficientes na descrição. | C10: Sim
A11: 10 | B11: Critério 1A (descrição insuficiente) – Um ou mais elementos indispensáveis ao entendimento do item não foram descritos e/ou podem não fazer parte do conhecimento imagético por parte da pessoa com deficiência visual. O participante possivelmente não será capaz de realizar o item por informações insuficientes na descrição. | C11: Sim
A12: 11 | B12: Critério 3A (Descrição suficiente e tempo suficiente) —A descrição apresenta de maneira devida todos os elementos indispensáveis ao entendimento do item em tempo adequado para a resolução. | C12: Não
A13: 12 | B13: Critério 3A (Descrição suficiente e tempo suficiente) —A descrição apresenta de maneira devida todos os elementos indispensáveis ao entendimento do item em tempo adequado para a resolução. | C13: Não
... A21: 20 | B21: Critério 3A (Descrição suficiente e tempo suficiente) —A descrição apresenta de maneira devida todos os elementos indispensáveis ao entendimento do item em tempo adequado para a resolução. | C21: Não

Sheet 2013
A1: Questão | B1: Critério de Acessibilidade Atribuído | C1: Elementos Visuais
A2: 1 | B2: Critério 3A (Descrição suficiente e tempo suficiente) —A descrição apresenta de maneira devida todos os elementos indispensáveis ao entendimento do item em tempo adequado para a resolução. | C2: Não
A3: 2 | B3: Critério 3A (Descrição suficiente e tempo suficiente) —A descrição apresenta de maneira devida todos os elementos indispensáveis ao entendimento do item em tempo adequado para a resolução. | C3: Não
A4: 3 | B4: Critério 3A (Descrição suficiente e tempo suficiente) —A descrição apresenta de maneira devida todos os elementos indispensáveis ao entendimento do item em tempo adequado para a resolução. | C4: Não
A5: 4 | B5: Critério 3A (Descrição suficiente e tempo suficiente) —A descrição apresenta de maneira devida todos os elementos indispensáveis ao entendimento do item em tempo adequado para a resolução. | C5: Não
A6: 5 | B6: Critério 3A (Descrição suficiente e tempo suficiente) —A descrição apresenta de maneira devida todos os elementos indispensáveis ao entendimento do item em tempo adequado para a resolução. | C6: Não
A7: 6 | B7: Critério 3A (Descrição suficiente e tempo suficiente) —A descrição apresenta de maneira devida todos os elementos indispensáveis ao entendimento do item em tempo adequado para a resolução. | C7: Não
A8: 7 | B8: Critério 3A (Descrição suficiente e tempo suficiente) —A descrição apresenta de maneira devida todos os elementos indispensáveis ao entendimento do item em tempo adequado para a resolução. | C8: Não
A9: 8 | B9: Critério 3A (Descrição suficiente e tempo suficiente) —A descrição apresenta de maneira devida todos os elementos indispensáveis ao entendimento do item em tempo adequado para a resolução. | C9: Não
A10: 9 | B10: Critério 3A (Descrição suficiente e tempo suficiente) —A descrição apresenta de maneira devida todos os elementos indispensáveis ao entendimento do item em tempo adequado para a resolução. | C10: Não
A11: 10 | B11: Critério 3A (Descrição suficiente e tempo suficiente) —A descrição apresenta de maneira devida todos os elementos indispensáveis ao entendimento do item em tempo adequado para a resolução. | C11: Não
A12: 11 | B12: Critério 3A (Descrição suficiente e tempo suficiente) —A descrição apresenta de maneira devida todos os elementos indispensáveis ao entendimento do item em tempo adequado para a resolução. | C12: Não
A13: 12 | B13: Critério 3A (Descrição suficiente e tempo suficiente) —A descrição apresenta de maneira devida todos os elementos indispensáveis ao entendimento do item em tempo adequado para a resolução. | C13: Não
... A21: 20 | B21: Critério 3A (Descrição suficiente e tempo suficiente) —A descrição apresenta de maneira devida todos os elementos indispensáveis ao entendimento do item em tempo adequado para a resolução. | C21: Não

Sheet 2014
A1: Questão | B1: Critério de Acessibilidade Atribuído | C1: Elementos Visuais
A2: 1 | B2: Critério 3A (Descrição suficiente e tempo suficiente) —A descrição apresenta de maneira devida todos os elementos indispensáveis ao entendimento do item em tempo adequado para a resolução. | C2: Não
A3: 2 | B3: Critério 1A (descrição insuficiente) – Um ou mais elementos indispensáveis ao entendimento do item não foram descritos e/ou podem não fazer parte do conhecimento imagético por parte da pessoa com deficiência visual. O participante possivelmente não será capaz de realizar o item por informações insuficientes na descrição. | C3: Sim
A4: 3 | B4: Critério 3A (Descrição suficiente e tempo suficiente) —A descrição apresenta de maneira devida todos os elementos indispensáveis ao entendimento do item em tempo adequado para a resolução. | C4: Não
A5: 4 | B5: Critério 1A (descrição insuficiente) – Um ou mais elementos indispensáveis ao entendimento do item não foram descritos e/ou podem não fazer parte do conhecimento imagético por parte da pessoa com deficiência visual. O participante possivelmente não será capaz de realizar o item por informações insuficientes na descrição. | C5: Sim
A6: 5 | B6: Critério 1A (descrição insuficiente) – Um ou mais elementos indispensáveis ao entendimento do item não foram descritos e/ou podem não fazer parte do conhecimento imagético por parte da pessoa com deficiência visual. O participante possivelmente não será capaz de realizar o item por informações insuficientes na descrição. | C6: Sim
A7: 6 | B7: Critério 3A (Descrição suficiente e tempo suficiente) —A descrição apresenta de maneira devida todos os elementos indispensáveis ao entendimento do item em tempo adequado para a resolução. | C7: Não
A8: 7 | B8: Critério 3A (Descrição suficiente e tempo suficiente) —A descrição apresenta de maneira devida todos os elementos indispensáveis ao entendimento do item em tempo adequado para a resolução. | C8: Não
A9: 8 | B9: Critério 3A (Descrição suficiente e tempo suficiente) —A descrição apresenta de maneira devida todos os elementos indispensáveis ao entendimento do item em tempo adequado para a resolução. | C9: Não
A10: 9 | B10: Critério 3A (Descrição suficiente e tempo suficiente) —A descrição apresenta de maneira devida todos os elementos indispensáveis ao entendimento do item em tempo adequado para a resolução. | C10: Não
A11: 10 | B11: Critério 3A (Descrição suficiente e tempo suficiente) —A descrição apresenta de maneira devida todos os elementos indispensáveis ao entendimento do item em tempo adequado para a resolução. | C11: Não
A12: 11 | B12: Critério 3A (Descrição suficiente e tempo suficiente) —A descrição apresenta de maneira devida todos os elementos indispensáveis ao entendimento do item em tempo adequado para a resolução. | C12: Não
A13: 12 | B13: Critério 3A (Descrição suficiente e tempo suficiente) —A descrição apresenta de maneira devida todos os elementos indispensáveis ao entendimento do item em tempo adequado para a resolução. | C13: Não
... A26: 25 | B26: Critério 3A (Descrição suficiente e tempo suficiente) —A descrição apresenta de maneira devida todos os elementos indispensáveis ao entendimento do item em tempo adequado para a resolução. | C26: Não

Sheet 2015
A1: Questão | B1: Critério de Acessibilidade Atribuído | C1: Elementos Visuais
A2: 1 | B2: Critério 3A (Descrição suficiente e tempo suficiente) —A descrição apresenta de maneira devida todos os elementos indispensáveis ao entendimento do item em tempo adequado para a resolução. | C2: Não
A3: 2 | B3: Critério 3A (Descrição suficiente e tempo suficiente) —A descrição apresenta de maneira devida todos os elementos indispensáveis ao entendimento do item em tempo adequado para a resolução. | C3: Não
A4: 3 | B4: Critério 1A (descrição insuficiente) – Um ou mais elementos indispensáveis ao entendimento do item não foram descritos e/ou podem não fazer parte do conhecimento imagético por parte da pessoa com deficiência visual. O participante possivelmente não será capaz de realizar o item por informações insuficientes na descrição. | C4: Sim
A5: 4 | B5: Critério 1A (descrição insuficiente) – Um ou mais elementos indispensáveis ao entendimento do item não foram descritos e/ou podem não fazer parte do conhecimento imagético por parte da pessoa com deficiência visual. O participante possivelmente não será capaz de realizar o item por informações insuficientes na descrição. | C5: Sim
A6: 5 | B6: Critério 1A (descrição insuficiente) – Um ou mais elementos indispensáveis ao entendimento do item não foram descritos e/ou podem não fazer parte do conhecimento imagético por parte da pessoa com deficiência visual. O participante possivelmente não será capaz de realizar o item por informações insuficientes na descrição. | C6: Sim
A7: 6 | B7: Critério 3A (Descrição suficiente e tempo suficiente) —A descrição apresenta de maneira devida todos os elementos indispensáveis ao entendimento do item em tempo adequado para a resolução. | C7: Não
A8: 7 | B8: Critério 3A (Descrição suficiente e tempo suficiente) —A descrição apresenta de maneira devida todos os elementos indispensáveis ao entendimento do item em tempo adequado para a resolução. | C8: Sim
A9: 8 | B9: Critério 1A (descrição insuficiente) – Um ou mais elementos indispensáveis ao entendimento do item não foram descritos e/ou podem não fazer parte do conhecimento imagético por parte da pessoa com deficiência visual. O participante possivelmente não será capaz de realizar o item por informações insuficientes na descrição. | C9: Sim
A10: 9 | B10: Critério 3A (Descrição suficiente e tempo suficiente) —A descrição apresenta de maneira devida todos os elementos indispensáveis ao entendimento do item em tempo adequado para a resolução. | C10: Não
A11: 10 | B11: Critério 3A (Descrição suficiente e tempo suficiente) —A descrição apresenta de maneira devida todos os elementos indispensáveis ao entendimento do item em tempo adequado para a resolução. | C11: Não
A12: 11 | B12: Critério 3A (Descrição suficiente e tempo suficiente) —A descrição apresenta de maneira devida todos os elementos indispensáveis ao entendimento do item em tempo adequado para a resolução. | C12: Não
A13: 12 | B13: Critério 3A (Descrição suficiente e tempo suficiente) —A descrição apresenta de maneira devida todos os elementos indispensáveis ao entendimento do item em tempo adequado para a resolução. | C13: Não
... A26: 25 | B26: Critério 3A (Descrição suficiente e tempo suficiente) —A descrição apresenta de maneira devida todos os elementos indispensáveis ao entendimento do item em tempo adequado para a resolução. | C26: Não

Sheet 2016
A1: Questão | B1: Critério de Acessibilidade Atribuído | C1: Elementos Visuais
A2: 1 | B2: Critério 1A (descrição insuficiente) – Um ou mais elementos indispensáveis ao entendimento do item não foram descritos e/ou podem não fazer parte do conhecimento imagético por parte da pessoa com deficiência visual. O participante possivelmente não será capaz de realizar o item por informações insuficientes na descrição. | C2: Sim
A3: 2 | B3: Critério 1A (descrição insuficiente) – Um ou mais elementos indispensáveis ao entendimento do item não foram descritos e/ou podem não fazer parte do conhecimento imagético por parte da pessoa com deficiência visual. O participante possivelmente não será capaz de realizar o item por informações insuficientes na descrição. | C3: Sim
A4: 3 | B4: Critério 1A (descrição insuficiente) – Um ou mais elementos indispensáveis ao entendimento do item não foram descritos e/ou podem não fazer parte do conhecimento imagético por parte da pessoa com deficiência visual. O participante possivelmente não será capaz de realizar o item por informações insuficientes na descrição. | C4: Sim
A5: 4 | B5: Critério 3A (Descrição suficiente e tempo suficiente) —A descrição apresenta de maneira devida todos os elementos indispensáveis ao entendimento do item em tempo adequado para a resolução. | C5: Não
A6: 5 | B6: Critério 3A (Descrição suficiente e tempo suficiente) —A descrição apresenta de maneira devida todos os elementos indispensáveis ao entendimento do item em tempo adequado para a resolução. | C6: Não
A7: 6 | B7: Critério 3A (Descrição suficiente e tempo suficiente) —A descrição apresenta de maneira devida todos os elementos indispensáveis ao entendimento do item em tempo adequado para a resolução. | C7: Não
A8: 7 | B8: Critério 3A (Descrição suficiente e tempo suficiente) —A descrição apresenta de maneira devida todos os elementos indispensáveis ao entendimento do item em tempo adequado para a resolução. | C8: Não
A9: 8 | B9: Critério 1A (descrição insuficiente) – Um ou mais elementos indispensáveis ao entendimento do item não foram descritos e/ou podem não fazer parte do conhecimento imagético por parte da pessoa com deficiência visual. O participante possivelmente não será capaz de realizar o item por informações insuficientes na descrição. | C9: Sim
A10: 9 | B10: Critério 1A (descrição insuficiente) – Um ou mais elementos indispensáveis ao entendimento do item não foram descritos e/ou podem não fazer parte do conhecimento imagético por parte da pessoa com deficiência visual. O participante possivelmente não será capaz de realizar o item por informações insuficientes na descrição. | C10: Sim
A11: 10 | B11: Critério 1A (descrição insuficiente) – Um ou mais elementos indispensáveis ao entendimento do item não foram descritos e/ou podem não fazer parte do conhecimento imagético por parte da pessoa com deficiência visual. O participante possivelmente não será capaz de realizar o item por informações insuficientes na descrição. | C11: Sim
A12: 11 | B12: Critério 3A (Descrição suficiente e tempo suficiente) —A descrição apresenta de maneira devida todos os elementos indispensáveis ao entendimento do item em tempo adequado para a resolução. | C12: Não
A13: 12 | B13: Critério 3A (Descrição suficiente e tempo suficiente) —A descrição apresenta de maneira devida todos os elementos indispensáveis ao entendimento do item em tempo adequado para a resolução. | C13: Não
... A26: 25 | B26: Critério 3A (Descrição suficiente e tempo suficiente) —A descrição apresenta de maneira devida todos os elementos indispensáveis ao entendimento do item em tempo adequado para a resolução. | C26: Não

Sheet 2017
A1: Questão | B1: Critério de Acessibilidade Atribuído | C1: Elementos Visuais
A2: 1 | B2: Critério 3A (Descrição suficiente e tempo suficiente) —A descrição apresenta de maneira devida todos os elementos indispensáveis ao entendimento do item em tempo adequado para a resolução. | C2: Não
A3: 2 | B3: Critério 3A (Descrição suficiente e tempo suficiente) —A descrição apresenta de maneira devida todos os elementos indispensáveis ao entendimento do item em tempo adequado para a resolução. | C3: Não
A4: 3 | B4: Critério 3A (Descrição suficiente e tempo suficiente) —A descrição apresenta de maneira devida todos os elementos indispensáveis ao entendimento do item em tempo adequado para a resolução. | C4: Não
A5: 4 | B5: Critério 3A (Descrição suficiente e tempo suficiente) —A descrição apresenta de maneira devida todos os elementos indispensáveis ao entendimento do item em tempo adequado para a resolução. | C5: Não
A6: 5 | B6: Critério 3A (Descrição suficiente e tempo suficiente) —A descrição apresenta de maneira devida todos os elementos indispensáveis ao entendimento do item em tempo adequado para a resolução. | C6: Não
A7: 6 | B7: Critério 3A (Descrição suficiente e tempo suficiente) —A descrição apresenta de maneira devida todos os elementos indispensáveis ao entendimento do item em tempo adequado para a resolução. | C7: Não
A8: 7 | B8: Critério 3A (Descrição suficiente e tempo suficiente) —A descrição apresenta de maneira devida todos os elementos indispensáveis ao entendimento do item em tempo adequado para a resolução. | C8: Não
A9: 8 | B9: Critério 3A (Descrição suficiente e tempo suficiente) —A descrição apresenta de maneira devida todos os elementos indispensáveis ao entendimento do item em tempo adequado para a resolução. | C9: Não
A10: 9 | B10: Critério 3A (Descrição suficiente e tempo suficiente) —A descrição apresenta de maneira devida todos os elementos indispensáveis ao entendimento do item em tempo adequado para a resolução. | C10: Não
A11: 10 | B11: Critério 3A (Descrição suficiente e tempo suficiente) —A descrição apresenta de maneira devida todos os elementos indispensáveis ao entendimento do item em tempo adequado para a resolução. | C11: Não
A12: 11 | B12: Critério 3A (Descrição suficiente e tempo suficiente) —A descrição apresenta de maneira devida todos os elementos indispensáveis ao entendimento do item em tempo adequado para a resolução. | C12: Não
A13: 12 | B13: Critério 3A (Descrição suficiente e tempo suficiente) —A descrição apresenta de maneira devida todos os elementos indispensáveis ao entendimento do item em tempo adequado para a resolução. | C13: Não
... A16: 15 | B16: Critério 3A (Descrição suficiente e tempo suficiente) —A descrição apresenta de maneira devida todos os elementos indispensáveis ao entendimento do item em tempo adequado para a resolução. | C16: Não

Sheet 2018 N1
A1: Questão | B1: Critério de Acessibilidade Atribuído | C1: Elementos Visuais
A2: 1 | B2: Critério 1A (descrição insuficiente) – Um ou mais elementos indispensáveis ao entendimento do item não foram descritos e/ou podem não fazer parte do conhecimento imagético por parte da pessoa com deficiência visual. O participante possivelmente não será capaz de realizar o item por informações insuficientes na descrição. | C2: Sim
A3: 2 | B3: Critério 1A (descrição insuficiente) – Um ou mais elementos indispensáveis ao entendimento do item não foram descritos e/ou podem não fazer parte do conhecimento imagético por parte da pessoa com deficiência visual. O participante possivelmente não será capaz de realizar o item por informações insuficientes na descrição. | C3: Sim
A4: 3 | B4: Critério 1A (descrição insuficiente) – Um ou mais elementos indispensáveis ao entendimento do item não foram descritos e/ou podem não fazer parte do conhecimento imagético por parte da pessoa com deficiência visual. O participante possivelmente não será capaz de realizar o item por informações insuficientes na descrição. | C4: Sim
A5: 4 | B5: Critério 1A (descrição insuficiente) – Um ou mais elementos indispensáveis ao entendimento do item não foram descritos e/ou podem não fazer parte do conhecimento imagético por parte da pessoa com deficiência visual. O participante possivelmente não será capaz de realizar o item por informações insuficientes na descrição. | C5: Sim
A6: 5 | B6: Critério 1A (descrição insuficiente) – Um ou mais elementos indispensáveis ao entendimento do item não foram descritos e/ou podem não fazer parte do conhecimento imagético por parte da pessoa com deficiência visual. O participante possivelmente não será capaz de realizar o item por informações insuficientes na descrição. | C6: Sim
A7: 6 | B7: Critério 1A (descrição insuficiente) – Um ou mais elementos indispensáveis ao entendimento do item não foram descritos e/ou podem não fazer parte do conhecimento imagético por parte da pessoa com deficiência visual. O participante possivelmente não será capaz de realizar o item por informações insuficientes na descrição. | C7: Sim
A8: 7 | B8: Critério 3A (Descrição suficiente e tempo suficiente) —A descrição apresenta de maneira devida todos os elementos indispensáveis ao entendimento do item em tempo adequado para a resolução. | C8: Não
A9: 8 | B9: Critério 3A (Descrição suficiente e tempo suficiente) —A descrição apresenta de maneira devida todos os elementos indispensáveis ao entendimento do item em tempo adequado para a resolução. | C9: Não
A10: 9 | B10: Critério 3A (Descrição suficiente e tempo suficiente) —A descrição apresenta de maneira devida todos os elementos indispensáveis ao entendimento do item em tempo adequado para a resolução. | C10: Não
A11: 10 | B11: Critério 3A (Descrição suficiente e tempo suficiente) —A descrição apresenta de maneira devida todos os elementos indispensáveis ao entendimento do item em tempo adequado para a resolução. | C11: Não
A12: 11 | B12: Critério 3A (Descrição suficiente e tempo suficiente) —A descrição apresenta de maneira devida todos os elementos indispensáveis ao entendimento do item em tempo adequado para a resolução. | C12: Não
A13: 12 | B13: Critério 3A (Descrição suficiente e tempo suficiente) —A descrição apresenta de maneira devida todos os elementos indispensáveis ao entendimento do item em tempo adequado para a resolução. | C13: Não
... A16: 15 | B16: Critério 3A (Descrição suficiente e tempo suficiente) —A descrição apresenta de maneira devida todos os elementos indispensáveis ao entendimento do item em tempo adequado para a resolução. | C16: Não

Sheet 2018 N J
A1: Questão | B1: Critério de Acessibilidade Atribuído | C1: Elementos Visuais
A2: 1 | B2: Critério 3A (Descrição suficiente e tempo suficiente) —A descrição apresenta de maneira devida todos os elementos indispensáveis ao entendimento do item em tempo adequado para a resolução. | C2: Não
A3: 2 | B3: Critério 3A (Descrição suficiente e tempo suficiente) —A descrição apresenta de maneira devida todos os elementos indispensáveis ao entendimento do item em tempo adequado para a resolução. | C3: Não
A4: 3 | B4: Critério 1A (descrição insuficiente) – Um ou mais elementos indispensáveis ao entendimento do item não foram descritos e/ou podem não fazer parte do conhecimento imagético por parte da pessoa com deficiência visual. O participante possivelmente não será capaz de realizar o item por informações insuficientes na descrição. | C4: Sim
A5: 4 | B5: Critério 1A (descrição insuficiente) – Um ou mais elementos indispensáveis ao entendimento do item não foram descritos e/ou podem não fazer parte do conhecimento imagético por parte da pessoa com deficiência visual. O participante possivelmente não será capaz de realizar o item por informações insuficientes na descrição. | C5: Sim
A6: 5 | B6: Critério 1A (descrição insuficiente) – Um ou mais elementos indispensáveis ao entendimento do item não foram descritos e/ou podem não fazer parte do conhecimento imagético por parte da pessoa com deficiência visual. O participante possivelmente não será capaz de realizar o item por informações insuficientes na descrição. | C6: Sim
A7: 6 | B7: Critério 1A (descrição insuficiente) – Um ou mais elementos indispensáveis ao entendimento do item não foram descritos e/ou podem não fazer parte do conhecimento imagético por parte da pessoa com deficiência visual. O participante possivelmente não será capaz de realizar o item por informações insuficientes na descrição. | C7: Sim
A8: 7 | B8: Critério 1A (descrição insuficiente) – Um ou mais elementos indispensáveis ao entendimento do item não foram descritos e/ou podem não fazer parte do conhecimento imagético por parte da pessoa com deficiência visual. O participante possivelmente não será capaz de realizar o item por informações insuficientes na descrição. | C8: Sim
A9: 8 | B9: Critério 1A (descrição insuficiente) – Um ou mais elementos indispensáveis ao entendimento do item não foram descritos e/ou podem não fazer parte do conhecimento imagético por parte da pessoa com deficiência visual. O participante possivelmente não será capaz de realizar o item por informações insuficientes na descrição. | C9: Sim
A10: 9 | B10: Critério 3A (Descrição suficiente e tempo suficiente) —A descrição apresenta de maneira devida todos os elementos indispensáveis ao entendimento do item em tempo adequado para a resolução. | C10: Não
A11: 10 | B11: Critério 3A (Descrição suficiente e tempo suficiente) —A descrição apresenta de maneira devida todos os elementos indispensáveis ao entendimento do item em tempo adequado para a resolução. | C11: Não
A12: 11 | B12: Critério 3A (Descrição suficiente e tempo suficiente) —A descrição apresenta de maneira devida todos os elementos indispensáveis ao entendimento do item em tempo adequado para a resolução. | C12: Não
A13: 12 | B13: Critério 3A (Descrição suficiente e tempo suficiente) —A descrição apresenta de maneira devida todos os elementos indispensáveis ao entendimento do item em tempo adequado para a resolução. | C13: Não
... A16: 15 | B16: Critério 3A (Descrição suficiente e tempo suficiente) —A descrição apresenta de maneira devida todos os elementos indispensáveis ao entendimento do item em tempo adequado para a resolução. | C16: Não

Sheet 2019 N1
A1: Questão | B1: Critério de Acessibilidade Atribuído | C1: Elementos Visuais
A2: 1 | B2: Critério 1A (descrição insuficiente) – Um ou mais elementos indispensáveis ao entendimento do item não foram descritos e/ou podem não fazer parte do conhecimento imagético por parte da pessoa com deficiência visual. O participante possivelmente não será capaz de realizar o item por informações insuficientes na descrição. | C2: Sim
A3: 2 | B3: Critério 1A (descrição insuficiente) – Um ou mais elementos indispensáveis ao entendimento do item não foram descritos e/ou podem não fazer parte do conhecimento imagético por parte da pessoa com deficiência visual. O participante possivelmente não será capaz de realizar o item por informações insuficientes na descrição. | C3: Sim
A4: 3 | B4: Critério 3A (Descrição suficiente e tempo suficiente) —A descrição apresenta de maneira devida todos os elementos indispensáveis ao entendimento do item em tempo adequado para a resolução. | C4: Não
A5: 4 | B5: Critério 3A (Descrição suficiente e tempo suficiente) —A descrição apresenta de maneira devida todos os elementos indispensáveis ao entendimento do item em tempo adequado para a resolução. | C5: Não
A6: 5 | B6: Critério 1A (descrição insuficiente) – Um ou mais elementos indispensáveis ao entendimento do item não foram descritos e/ou podem não fazer parte do conhecimento imagético por parte da pessoa com deficiência visual. O participante possivelmente não será capaz de realizar o item por informações insuficientes na descrição. | C6: Sim
A7: 6 | B7: Critério 1A (descrição insuficiente) – Um ou mais elementos indispensáveis ao entendimento do item não foram descritos e/ou podem não fazer parte do conhecimento imagético por parte da pessoa com deficiência visual. O participante possivelmente não será capaz de realizar o item por informações insuficientes na descrição. | C7: Sim
A8: 7 | B8: Critério 3A (Descrição suficiente e tempo suficiente) —A descrição apresenta de maneira devida todos os elementos indispensáveis ao entendimento do item em tempo adequado para a resolução. | C8: Não
A9: 8 | B9: Critério 3A (Descrição suficiente e tempo suficiente) —A descrição apresenta de maneira devida todos os elementos indispensáveis ao entendimento do item em tempo adequado para a resolução. | C9: Não
A10: 9 | B10: Critério 3A (Descrição suficiente e tempo suficiente) —A descrição apresenta de maneira devida todos os elementos indispensáveis ao entendimento do item em tempo adequado para a resolução. | C10: Não
A11: 10 | B11: Critério 3A (Descrição suficiente e tempo suficiente) —A descrição apresenta de maneira devida todos os elementos indispensáveis ao entendimento do item em tempo adequado para a resolução. | C11: Não
A12: 11 | B12: Critério 3A (Descrição suficiente e tempo suficiente) —A descrição apresenta de maneira devida todos os elementos indispensáveis ao entendimento do item em tempo adequado para a resolução. | C12: Não
A13: 12 | B13: Critério 3A (Descrição suficiente e tempo suficiente) —A descrição apresenta de maneira devida todos os elementos indispensáveis ao entendimento do item em tempo adequado para a resolução. | C13: Não
... A16: 15 | B16: Critério 3A (Descrição suficiente e tempo suficiente) —A descrição apresenta de maneira devida todos os elementos indispensáveis ao entendimento do item em tempo adequado para a resolução. | C16: Não

Sheet 2019 N J
A1: Questão | B1: Critério de Acessibilidade Atribuído | C1: Elementos Visuais
A2: 1 | B2: Critério 3A (Descrição suficiente e tempo suficiente) —A descrição apresenta de maneira devida todos os elementos indispensáveis ao entendimento do item em tempo adequado para a resolução. | C2: Não
A3: 2 | B3: Critério 3A (Descrição suficiente e tempo suficiente) —A descrição apresenta de maneira devida todos os elementos indispensáveis ao entendimento do item em tempo adequado para a resolução. | C3: Não
A4: 3 | B4: Critério 1A (descrição insuficiente) – Um ou mais elementos indispensáveis ao entendimento do item não foram descritos e/ou podem não fazer parte do conhecimento imagético por parte da pessoa com deficiência visual. O participante possivelmente não será capaz de realizar o item por informações insuficientes na descrição. | C4: Sim
A5: 4 | B5: Critério 3A (Descrição suficiente e tempo suficiente) —A descrição apresenta de maneira devida todos os elementos indispensáveis ao entendimento do item em tempo adequado para a resolução. | C5: Sim
A6: 5 | B6: Critério 3A (Descrição suficiente e tempo suficiente) —A descrição apresenta de maneira devida todos os elementos indispensáveis ao entendimento do item em tempo adequado para a resolução. | C6: Sim
A7: 6 | B7: Critério 1A (descrição insuficiente) – Um ou mais elementos indispensáveis ao entendimento do item não foram descritos e/ou podem não fazer parte do conhecimento imagético por parte da pessoa com deficiência visual. O participante possivelmente não será capaz de realizar o item por informações insuficientes na descrição. | C7: Sim
A8: 7 | B8: Critério 1A (descrição insuficiente) – Um ou mais elementos indispensáveis ao entendimento do item não foram descritos e/ou podem não fazer parte do conhecimento imagético por parte da pessoa com deficiência visual. O participante possivelmente não será capaz de realizar o item por informações insuficientes na descrição. | C8: Sim
A9: 8 | B9: Critério 3A (Descrição suficiente e tempo suficiente) —A descrição apresenta de maneira devida todos os elementos indispensáveis ao entendimento do item em tempo adequado para a resolução. | C9: Não
A10: 9 | B10: Critério 3A (Descrição suficiente e tempo suficiente) —A descrição apresenta de maneira devida todos os elementos indispensáveis ao entendimento do item em tempo adequado para a resolução. | C10: Não
A11: 10 | B11: Critério 1A (descrição insuficiente) – Um ou mais elementos indispensáveis ao entendimento do item não foram descritos e/ou podem não fazer parte do conhecimento imagético por parte da pessoa com deficiência visual. O participante possivelmente não será capaz de realizar o item por informações insuficientes na descrição. | C11: Sim
A12: 11 | B12: Critério 3A (Descrição suficiente e tempo suficiente) —A descrição apresenta de maneira devida todos os elementos indispensáveis ao entendimento do item em tempo adequado para a resolução. | C12: Sim
A13: 12 | B13: Critério 1A (descrição insuficiente) – Um ou mais elementos indispensáveis ao entendimento do item não foram descritos e/ou podem não fazer parte do conhecimento imagético por parte da pessoa com deficiência visual. O participante possivelmente não será capaz de realizar o item por informações insuficientes na descrição. | C13: Sim
... A16: 15 | B16: Critério 3A (Descrição suficiente e tempo suficiente) —A descrição apresenta de maneira devida todos os elementos indispensáveis ao entendimento do item em tempo adequado para a resolução. | C16: Não

Sheet 2020 N1 A
A1: Questão | B1: Critério de Acessibilidade Atribuído | C1: Elementos Visuais
A2: 1 | B2: Critério 1A (descrição insuficiente) – Um ou mais elementos indispensáveis ao entendimento do item não foram descritos e/ou podem não fazer parte do conhecimento imagético por parte da pessoa com deficiência visual. O participante possivelmente não será capaz de realizar o item por informações insuficientes na descrição. | C2: Sim
A3: 2 | B3: Critério 3A (Descrição suficiente e tempo suficiente) —A descrição apresenta de maneira devida todos os elementos indispensáveis ao entendimento do item em tempo adequado para a resolução. | C3: Não
A4: 3 | B4: Critério 3A (Descrição suficiente e tempo suficiente) —A descrição apresenta de maneira devida todos os elementos indispensáveis ao entendimento do item em tempo adequado para a resolução. | C4: Não
A5: 4 | B5: Critério 1A (descrição insuficiente) – Um ou mais elementos indispensáveis ao entendimento do item não foram descritos e/ou podem não fazer parte do conhecimento imagético por parte da pessoa com deficiência visual. O participante possivelmente não será capaz de realizar o item por informações insuficientes na descrição. | C5: Sim
A6: 5 | B6: Critério 3A (Descrição suficiente e tempo suficiente) —A descrição apresenta de maneira devida todos os elementos indispensáveis ao entendimento do item em tempo adequado para a resolução. | C6: Não
A7: 6 | B7: Critério 3A (Descrição suficiente e tempo suficiente) —A descrição apresenta de maneira devida todos os elementos indispensáveis ao entendimento do item em tempo adequado para a resolução. | C7: Não
A8: 7 | B8: Critério 1A (descrição insuficiente) – Um ou mais elementos indispensáveis ao entendimento do item não foram descritos e/ou podem não fazer parte do conhecimento imagético por parte da pessoa com deficiência visual. O participante possivelmente não será capaz de realizar o item por informações insuficientes na descrição. | C8: Sim
A9: 8 | B9: Critério 3A (Descrição suficiente e tempo suficiente) —A descrição apresenta de maneira devida todos os elementos indispensáveis ao entendimento do item em tempo adequado para a resolução. | C9: Não
A10: 9 | B10: Critério 3A (Descrição suficiente e tempo suficiente) —A descrição apresenta de maneira devida todos os elementos indispensáveis ao entendimento do item em tempo adequado para a resolução. | C10: Não
A11: 10 | B11: Critério 3A (Descrição suficiente e tempo suficiente) —A descrição apresenta de maneira devida todos os elementos indispensáveis ao entendimento do item em tempo adequado para a resolução. | C11: Não
A12: 11 | B12: Critério 3A (Descrição suficiente e tempo suficiente) —A descrição apresenta de maneira devida todos os elementos indispensáveis ao entendimento do item em tempo adequado para a resolução. | C12: Não
A13: 12 | B13: Critério 3A (Descrição suficiente e tempo suficiente) —A descrição apresenta de maneira devida todos os elementos indispensáveis ao entendimento do item em tempo adequado para a resolução. | C13: Não
... A16: 15 | B16: Critério 3A (Descrição suficiente e tempo suficiente) —A descrição apresenta de maneira devida todos os elementos indispensáveis ao entendimento do item em tempo adequado para a resolução. | C16: Não

Sheet 2020 N1 B
A1: Questão | B1: Critério de Acessibilidade Atribuído | C1: Elementos Visuais
A2: 1 | B2: Critério 1A (descrição insuficiente) – Um ou mais elementos indispensáveis ao entendimento do item não foram descritos e/ou podem não fazer parte do conhecimento imagético por parte da pessoa com deficiência visual. O participante possivelmente não será capaz de realizar o item por informações insuficientes na descrição. | C2: Sim
A3: 2 | B3: Critério 1A (descrição insuficiente) – Um ou mais elementos indispensáveis ao entendimento do item não foram descritos e/ou podem não fazer parte do conhecimento imagético por parte da pessoa com deficiência visual. O participante possivelmente não será capaz de realizar o item por informações insuficientes na descrição. | C3: Sim
A4: 3 | B4: Critério 3A (Descrição suficiente e tempo suficiente) —A descrição apresenta de maneira devida todos os elementos indispensáveis ao entendimento do item em tempo adequado para a resolução. | C4: Não
A5: 4 | B5: Critério 3A (Descrição suficiente e tempo suficiente) —A descrição apresenta de maneira devida todos os elementos indispensáveis ao entendimento do item em tempo adequado para a resolução. | C5: Não
A6: 5 | B6: Critério 1A (descrição insuficiente) – Um ou mais elementos indispensáveis ao entendimento do item não foram descritos e/ou podem não fazer parte do conhecimento imagético por parte da pessoa com deficiência visual. O participante possivelmente não será capaz de realizar o item por informações insuficientes na descrição. | C6: Sim
A7: 6 | B7: Critério 1A (descrição insuficiente) – Um ou mais elementos indispensáveis ao entendimento do item não foram descritos e/ou podem não fazer parte do conhecimento imagético por parte da pessoa com deficiência visual. O participante possivelmente não será capaz de realizar o item por informações insuficientes na descrição. | C7: Sim
